Traceback (most recent call last):
  File "C:\Users\ricoi\PycharmProjects\banbot\.venv\lib\site-packages\discord\app_commands\commands.py", line 827, in _do_call
    return await self._callback(self.binding, interaction, **params)  # type: ignore
  File "C:\Users\ricoi\PycharmProjects\banbot\modules\utility.py", line 70, in appeal
    if guild in appeals:
TypeError: argument of type 'NoneType' is not iterable

The above exception was the direct cause of the following exception:

Traceback (most recent call last):
  File "C:\Users\ricoi\PycharmProjects\banbot\.venv\lib\site-packages\discord\app_commands\tree.py", line 1248, in _call
    await command._invoke_with_namespace(interaction, namespace)
  File "C:\Users\ricoi\PycharmProjects\banbot\.venv\lib\site-packages\discord\app_commands\commands.py", line 853, in _invoke_with_namespace
    return await self._do_call(interaction, transformed_values)
  File "C:\Users\ricoi\PycharmProjects\banbot\.venv\lib\site-packages\discord\app_commands\commands.py", line 842, in _do_call
    raise CommandInvokeError(self, e) from e
discord.app_commands.errors.CommandInvokeError: Command 'appeal' raised an exception: TypeError: argument of type 'NoneType' is not iterable
